Workbook

Sheet TABLE
F2: 1 MODULE
F4: Table format | S4: POINTS TO BE NOTED
B6: TABLE FORMAT | L6: RANGE FORMAT
S7: DATA SORTING = in table
B8: CLASS 10TH STUDENTS | L8: CLASS 10TH STUDENTS
B9: S.NO | C9: Name | D9: English | E9: Maths | F9: Science | G9: Hindi | L9: S.NO | M9: Name | N9: English | O9: Maths | P9: Science | Q9: Hindi
B10: 1 | C10: Aarav Sharma | D10: 85 | E10: 47 | F10: 22 | G10: 39 | L10: 1 | M10: Aarav Sharma | N10: 85 | O10: 47 | P10: 22 | Q10: 39
B11: 2 | C11: Aditi Mehta | D11: 92 | E11: 33 | F11: 56 | G11: 78 | L11: 2 | M11: Aditi Mehta | N11: 92 | O11: 33 | P11: 56 | Q11: 78
B12: 3 | C12: Rohan Kumar | D12: 78 | E12: 15 | F12: 91 | G12: 64 | L12: 3 | M12: Rohan Kumar | N12: 78 | O12: 15 | P12: 91 | Q12: 64
B13: 4 | C13: Isha Patel | D13: 88 | E13: 29 | F13: 43 | G13: 50 | L13: 4 | M13: Isha Patel | O13: 29 | P13: 43 | Q13: 50
B14: 5 | C14: Anaya Gupta | D14: 95 | E14: 67 | F14: 85 | G14: 19 | L14: 5 | M14: Anaya Gupta | N14: 95 | O14: 67 | P14: 85 | Q14: 19
B15: 6 | C15: Aryan Singh | D15: 81 | E15: 24 | F15: 72 | G15: 88 | L15: 6 | M15: Aryan Singh | N15: 81 | O15: 24 | P15: 72 | Q15: 88
B16: 7 | C16: Neha Reddy | D16: 89 | E16: 31 | F16: 18 | G16: 75 | L16: 7 | M16: Neha Reddy | N16: 89 | O16: 31 | P16: 18 | Q16: 75
B17: 8 | C17: Kabir Joshi | D17: 76 | E17: 58 | F17: 92 | G17: 13 | L17: 8 | M17: Kabir Joshi | N17: 76 | O17: 58 | P17: 92 | Q17: 13
B18: 9 | C18: Sneha Desai | D18: 91 | E18: 44 | F18: 38 | G18: 61 | L18: 9 | M18: Sneha Desai | N18: 91 | O18: 44 | P18: 38 | Q18: 61
B19: 10 | C19: Vihaan Rao | D19: 84 | E19: 76 | F19: 53 | G19: 27 | L19: 10 | M19: Vihaan Rao | N19: 84 | O19: 76 | P19: 53 | Q19: 27
H23: LOGICAL CALCULATION
H25: FIND OUT DAYS WE LIVE ON EARTH
H27: We only know | I27: CURRENT DATE | J27: DATE OF BIRTH | K27: Days we live on earth (FIND)
H28: DATE | I28: =TODAY() -> 45722 | J28: 26523 | K28: =I28-J28 -> 19199
H31: We only know | I31: CURRENT DATE | J31: Days we live on earth | K31: DATE OF BIRTH (FIND)
H32: Days | I32: =TODAY() -> 45722 | J32: 6386 | K32: =I32-J32 -> 39336
H35: We only know | I35: Total days | J35: Hours we lived on earth(F) | K35: Minutes we live on earth(F)
H36: Days | I36: 19170 | J36: =I36*24 -> 460080 | K36: =J36*60 -> 27604800
H39: We only know | I39: Total days | J39: Age of a Person
H40: Days | I40: 4078 | J40: =INT(I40/365.5) -> 11
H42: We only know | I42: DATE OF BIRTH | J42: Age of a Person
H43: DATE OF BIRTH | I43: 26523 | J43: =INT((TODAY()-I43)/365.5) -> 52

Sheet PASTE SPECIAL
G2: 2 MODULE
G4: Paste special function | R4: POINTS TO BE NOTED
D6: FN RANDOMBETWEEN (VARIABLE) | K6: FN RANDOMBETWEEN (Constant)
R7: fn = function
C8: =RANDBETWEEN(30,500) -> 276 | D8: =RANDBETWEEN(30,500) -> 131 | E8: =RANDBETWEEN(30,500) -> 424 | F8: =RANDBETWEEN(30,500) -> 120 | G8: =RANDBETWEEN(30,500) -> 457 | H8: =RANDBETWEEN(30,500) -> 247 | J8: 249 | K8: 171 | L8: 458 | M8: 150 | N8: 303 | O8: 308
C9: =RANDBETWEEN(30,500) -> 373 | D9: =RANDBETWEEN(30,500) -> 241 | E9: =RANDBETWEEN(30,500) -> 329 | F9: =RANDBETWEEN(30,500) -> 57 | G9: =RANDBETWEEN(30,500) -> 395 | H9: =RANDBETWEEN(30,500) -> 492 | J9: 282 | K9: 280 | L9: 80 | M9: 259 | N9: 68 | O9: 271 | R9: to make constant used paste special
C10: =RANDBETWEEN(30,500) -> 304 | D10: =RANDBETWEEN(30,500) -> 290 | E10: =RANDBETWEEN(30,500) -> 366 | F10: =RANDBETWEEN(30,500) -> 32 | G10: =RANDBETWEEN(30,500) -> 315 | H10: =RANDBETWEEN(30,500) -> 131 | J10: 339 | K10: 171 | L10: 51 | M10: 380 | N10: 122 | O10: 494 | R10: Paste shortcut = ctrl + alt + v
C11: =RANDBETWEEN(30,500) -> 318 | D11: =RANDBETWEEN(30,500) -> 320 | E11: =RANDBETWEEN(30,500) -> 440 | F11: =RANDBETWEEN(30,500) -> 428 | G11: =RANDBETWEEN(30,500) -> 49 | H11: =RANDBETWEEN(30,500) -> 447 | J11: 307 | K11: 76 | L11: 144 | M11: 44 | N11: 440 | O11: 429
C12: =RANDBETWEEN(30,500) -> 276 | D12: =RANDBETWEEN(30,500) -> 381 | E12: =RANDBETWEEN(30,500) -> 331 | F12: =RANDBETWEEN(30,500) -> 160 | G12: =RANDBETWEEN(30,500) -> 374 | H12: =RANDBETWEEN(30,500) -> 345 | J12: 454 | K12: 47 | L12: 163 | M12: 82 | N12: 325 | O12: 96 | R12: Go to shortcut = ctrl + g
C13: =RANDBETWEEN(30,500) -> 394 | D13: =RANDBETWEEN(30,500) -> 421 | E13: =RANDBETWEEN(30,500) -> 386 | F13: =RANDBETWEEN(30,500) -> 415 | G13: =RANDBETWEEN(30,500) -> 213 | H13: =RANDBETWEEN(30,500) -> 257 | J13: 228 | K13: 77 | L13: 398 | M13: 244 | N13: 123 | O13: 38 | R13: [Go to] fn helps in finding require cell
C14: =RANDBETWEEN(30,500) -> 119 | D14: =RANDBETWEEN(30,500) -> 473 | E14: =RANDBETWEEN(30,500) -> 423 | F14: =RANDBETWEEN(30,500) -> 236 | G14: =RANDBETWEEN(30,500) -> 83 | H14: =RANDBETWEEN(30,500) -> 392 | J14: 72 | K14: 107 | L14: 238 | M14: 237 | N14: 160 | O14: 334
C15: =RANDBETWEEN(30,500) -> 54 | D15: =RANDBETWEEN(30,500) -> 293 | E15: =RANDBETWEEN(30,500) -> 343 | F15: =RANDBETWEEN(30,500) -> 79 | G15: =RANDBETWEEN(30,500) -> 351 | H15: =RANDBETWEEN(30,500) -> 328 | J15: 116 | K15: 196 | L15: 91 | M15: 266 | N15: 257 | O15: 217 | R15: find and replace = ctrl + f
C16: =RANDBETWEEN(30,500) -> 47 | D16: =RANDBETWEEN(30,500) -> 32 | E16: =RANDBETWEEN(30,500) -> 302 | F16: =RANDBETWEEN(30,500) -> 264 | G16: =RANDBETWEEN(30,500) -> 97 | H16: =RANDBETWEEN(30,500) -> 77 | J16: 120 | K16: 275 | L16: 150 | M16: 377 | N16: 349 | O16: 370 | R16: find and replace have some limitations
C17: =RANDBETWEEN(30,500) -> 201 | D17: =RANDBETWEEN(30,500) -> 116 | E17: =RANDBETWEEN(30,500) -> 380 | F17: =RANDBETWEEN(30,500) -> 480 | G17: =RANDBETWEEN(30,500) -> 329 | H17: =RANDBETWEEN(30,500) -> 390 | J17: 233 | K17: 350 | L17: 357 | M17: 292 | N17: 265 | O17: 123 | R17: we have give particular rule in format we get right things
C18: =RANDBETWEEN(30,500) -> 493 | D18: =RANDBETWEEN(30,500) -> 32 | E18: =RANDBETWEEN(30,500) -> 467 | F18: =RANDBETWEEN(30,500) -> 210 | G18: =RANDBETWEEN(30,500) -> 122 | H18: =RANDBETWEEN(30,500) -> 127 | J18: 47 | K18: 217 | L18: 448 | M18: 184 | N18: 99 | O18: 498
R19: transpose fn
R20: we used paste special to transpose required data
H22: find and replace example | R22: Flash fill
R23: Shortcut = Ctrl+E
G24: 249 | H24: 171 | I24: 458 | J24: 150 | K24: 303 | L24: 308
G25: 282 | H25: 280 | I25: 80 | J25: 259 | K25: 68 | L25: 271 | R25: HIDE SHORTCUTS
G26: 339 | H26: 171 | I26: 51 | J26: 380 | K26: 122 | L26: 494 | R26: Row = Ctrl+9
G27: 307 | H27: 76 | I27: 144 | J27: 44 | K27: 440 | L27: 429 | R27: Columns = Ctrl+0
G28: 454 | H28: 47 | I28: 163 | J28: 82 | K28: 325 | L28: 96
G29: 228 | H29: 77 | I29: 398 | J29: 244 | K29: 123 | L29: 38
G30: 72 | H30: nil | I30: 238 | J30: 237 | K30: nil | L30: 334
G31: 116 | H31: 196 | I31: 91 | J31: 266 | K31: 257 | L31: 217
G32: 120 | H32: 275 | I32: 150 | J32: 377 | K32: 349 | L32: 370
G33: 233 | H33: nil | I33: 357 | J33: 292 | K33: nil | L33: 123
G34: 47 | H34: 217 | I34: 448 | J34: 184 | K34: 99 | L34: 498
H39: Transpose fn in paste special
D41: Raw data
B43: 249 | C43: 171 | D43: 458 | E43: 150 | F43: 303 | G43: 308
B44: 282 | C44: 280 | D44: 80 | E44: 259 | F44: 68 | G44: 271
B45: 339 | C45: 171 | D45: 51 | E45: 380 | F45: 122 | G45: 494
B46: 307 | C46: 76 | D46: 144 | E46: 44 | F46: 440 | G46: 429
B47: 454 | C47: 47 | D47: 163 | E47: 82 | F47: 325 | G47: 96
B48: 228 | C48: 77 | D48: 398 | E48: 244 | F48: 123 | G48: 38
B49: 72 | C49: nil | D49: 238 | E49: 237 | F49: nil | G49: 334
B50: 116 | C50: 196 | D50: 91 | E50: 266 | F50: 257 | G50: 217
...

Sheet REFERENCE
C2: 3 MODULE
D4: RELATIVE REFERENCE
C7: Product | D7: Category | E7: Department | F7: Purchase Price | G7: Sale Price | H7: Profit/Loss
C8: Dry Tissues | D8: Cleaning Supplies | E8: Household | F8: 120 | G8: 135 | H8: =G8-F8 -> 15 | J8: =_xlfn.FORMULATEXT(H8) -> =G8-F8
C9: Paper Towels | D9: Cleaning Supplies | E9: Household | F9: 125 | G9: 135 | H9: =G9-F9 -> 10
C10: Wet Wipes | D10: Cleaning Supplies | E10: Household | F10: 120 | G10: 135 | H10: =G10-F10 -> 15
C11: Chicken Dinner | D11: Frozen Foods | E11: Grocery | F11: 80 | G11: 155 | H11: =G11-F11 -> 75
C12: Clear Refresher | D12: Soft Drinks | E12: Grocery | F12: 165 | G12: 100 | H12: =G12-F12 -> -65
C13: Dried Grits | D13: Salty Snacks | E13: Grocery | F13: 180 | G13: 100 | H13: =G13-F13 -> -80
C14: Extra Nougat | D14: Candy | E14: Grocery | F14: 145 | G14: 115 | H14: =G14-F14 -> -30
C15: Athletic Drink | D15: Soft Drinks | E15: Grocery | F15: 75 | G15: 155 | H15: =G15-F15 -> 80
C16: Stew | D16: Frozen Foods | E16: Grocery | F16: 80 | G16: 155 | H16: =G16-F16 -> 75
C17: Jerky | D17: Salty Snacks | E17: Grocery | F17: 160 | G17: 100 | H17: =G17-F17 -> -60
C18: Dry Tissues | D18: Cleaning Supplies | E18: Household | F18: 168 | G18: 100 | H18: =G18-F18 -> -68
C19: Paper Towels | D19: Cleaning Supplies | E19: Household | F19: 90 | G19: 155 | H19: =G19-F19 -> 65
C20: Wet Wipes | D20: Cleaning Supplies | E20: Household | F20: 120 | G20: 135 | H20: =G20-F20 -> 15
... C107: Jerky | D107: Salty Snacks | E107: Grocery | F107: 160 | G107: 100 | H107: =G107-F107 -> -60
F110: ABSOLUTE REFERENCE
C112: In these we fixed a cell value using dollar sign as shown in right side
K113: 0.12
C114: Date | D114: Order Number | E114: Customer | F114: Quantity | G114: Category | H114: Code | I114: Unit Price | J114: Gross Sales | K114: GST | L114: Amount
C115: 43072 | D115: 1 | E115: Hindol Sinha | F115: 5 | G115: Suits | H115: W1 | I115: 3200 | J115: 16000 | K115: =J115*$K$113 -> 1920 | L115: 16800 | N115: =_xlfn.FORMULATEXT(K115) -> =J115*$K$113
C116: 43074 | D116: 2 | E116: Dola Das | F116: 3 | G116: Coats | H116: H2 | I116: 1250 | J116: 3750 | K116: =J116*$K$113 -> 450 | L116: 3937.5
C117: 43079 | D117: 3 | E117: Deepak Sharma | F117: 4 | G117: Coats | H117: C4 | I117: 1250 | J117: 5000 | K117: =J117*$K$113 -> 600 | L117: 5250
C118: 43081 | D118: 4 | E118: Uma Nag | F118: 12 | G118: Ties | H118: T1 | I118: 150 | J118: 1800 | K118: =J118*$K$113 -> 216 | L118: 1890
C119: 43084 | D119: 5 | E119: Sayak Pal | F119: 6 | G119: Hats | H119: C1 | I119: 99 | J119: 594 | K119: =J119*$K$113 -> 71.28 | L119: 623.7
C120: 43089 | D120: 6 | E120: Srijan Das | F120: 10 | G120: Suits | H120: W1 | I120: 3200 | J120: 32000 | K120: =J120*$K$113 -> 3840 | L120: 33600
C121: 43090 | D121: 7 | E121: Srijita Agarwal | F121: 5 | G121: Shoes | H121: H1 | I121: 590 | J121: 2950 | K121: =J121*$K$113 -> 354 | L121: 3097.5
C122: 43092 | D122: 8 | E122: Rina Karmakar | F122: 2 | G122: Hats | H122: S2 | I122: 99 | J122: 198 | K122: =J122*$K$113 -> 23.76 | L122: 207.9
C123: 43095 | D123: 9 | E123: Lily Roy | F123: 10 | G123: Ties | H123: T5 | I123: 150 | J123: 1500 | K123: =J123*$K$113 -> 180 | L123: 1575
C124: 43099 | D124: 10 | E124: Sonali Gupta | F124: 5 | G124: Shoes | H124: S2 | I124: 590 | J124: 2950 | K124: =J124*$K$113 -> 354 | L124: 3097.5
C125: 43072 | D125: 11 | E125: Deepali Srivastava | F125: 3 | G125: Suits | H125: W1 | I125: 3200 | J125: 9600 | K125: =J125*$K$113 -> 1152 | L125: 10080
C126: 43074 | D126: 12 | E126: Rakhi | F126: 3 | G126: Coats | H126: H2 | I126: 1250 | J126: 3750 | K126: =J126*$K$113 -> 450 | L126: 3937.5
C127: 43079 | D127: 13 | E127: Deepak Chandra Fulara | F127: 4 | G127: Coats | H127: C4 | I127: 1250 | J127: 5000 | K127: =J127*$K$113 -> 600 | L127: 5250
... C194: 43099 | D194: 80 | E194: Deblina Ghatak | F194: 5 | G194: Shoes | H194: S2 | I194: 590 | J194: 2950 | K194: =J194*$K$113 -> 354 | L194: 3097.5
D197: MIXED REFERENCE
C199: In these we fixed a single row cell number using dollar sign as shown in right side for calculation
C202: Sales Person | D202: Target (in INR) | E202: 0.12 | F202: 0.08 | G202: 0.15 | H202: 0.25 | I202: 0.22 | J202: 0.18
E203: January | F203: February | G203: March | H203: April | I203: May | J203: June
C204: Jinia Ghosh | D204: 164506 | E204: =D204*E$202 -> 19740.72 | F204: =E204*F$202 -> 1579.2576 | G204: =F204*G$202 -> 236.88864 | H204: =G204*H$202 -> 59.22216 | I204: =H204*I$202 -> 13.028875 | J204: =I204*J$202 -> 2.3451975 | N204: =_xlfn.FORMULATEXT(E204) -> =D204*E$202
...

Sheet DATA ARRANGEMENT
E2: 4 MODULE
E4: DATA ARRANGEMENT | N4: POINTS TO BE NOTED
F6: text to column
N8: Rib (data) = txt to column
B9: Names | D9: first Name | E9: last name
B10: Rahul Sharma | D10: Rahul | E10: Sharma | N10: separate name in first and last using this fn
B11: Priya Patel | D11: Priya | E11: Patel | N11: we can do more things separate as per need
B12: Amit Singh | D12: Amit | E12: Singh
B13: Anjali Gupta | D13: Anjali | E13: Gupta | N13: Rib (data) = remove duplication fn
B14: Suresh Kumar | D14: Suresh | E14: Kumar | N14: remove same data from workbook/sheet( selected cells only)
B15: Pooja Reddy | D15: Pooja | E15: Reddy
B16: Vikram Malhotra | D16: Vikram | E16: Malhotra | N16: Rib (data) = Data validation
B17: Aarti Desai | D17: Aarti | E17: Desai | N17: validation means giving certain rules
B18: Arjun Choudhury | D18: Arjun | E18: Choudhury | N18: if not performed correctly it shows error
B19: Naina Iyer | D19: Naina | E19: Iyer | N19: formula for only txt and symbol =istext(A1:Z1)
B20: Rajesh Verma | D20: Rajesh | E20: Verma | N20: formula for only numbers =isnumber(A1:Z1)
B21: Kavita Mishra | D21: Kavita | E21: Mishra
B22: Aditya Joshi | D22: Aditya | E22: Joshi | N22: Data Protection
B23: Deepika Khanna | D23: Deepika | E23: Khanna | N23: Rib(review) = protect sheet
B24: Ravi Menon | D24: Ravi | E24: Menon | N24: if help to protect data from changes by any person
B25: Sneha Shah | D25: Sneha | E25: Shah
B26: Mohan Rao | D26: Mohan | E26: Rao
B27: Jaya Mehta | D27: Jaya | E27: Mehta
B28: Karthik Nair | D28: Karthik | E28: Nair
B29: Geeta Bhat | D29: Geeta | E29: Bhat
E33: Remove duplicate data
B35: RAW DATA | D35: using duplicate fn
B37: Names | D37: Names
B38: Rahul Sharma | D38: Rahul Sharma
B39: Priya Patel | D39: Priya Patel
B40: Amit Singh | D40: Amit Singh
B41: Anjali Gupta | D41: Anjali Gupta
B42: Suresh Kumar | D42: Suresh Kumar
B43: Pooja Reddy | D43: Pooja Reddy
B44: Vikram Malhotra | D44: Vikram Malhotra
B45: Aarti Desai | D45: Aarti Desai
B46: Arjun Choudhury | D46: Arjun Choudhury
B47: Naina Iyer | D47: Naina Iyer
... B57: Geeta Bhat | D57: Geeta Bhat
B58: Deepika Khanna
...

Sheet SUBTOTAL
B3: 5 MODULE
B5: Subtotal , Group and Ungroup | J5: POINTS TO BE NOTED
D7: Sale data of jacket by A Limited company
C9: City | D9: Item Number | E9: Quantity | F9: Price (per product, ₹) | G9: Amount (₹)
C10: Mumbai | D10: 1 | E10: 50 | F10: 1500 | G10: 75000
C11: Delhi | D11: 2 | E11: 45 | F11: 1600 | G11: 72000
C12: Bangalore | D12: 3 | E12: 55 | F12: 1450 | G12: 79750
C13: Kolkata | D13: 4 | E13: 40 | F13: 1700 | G13: 68000
C14: Chennai | D14: 5 | E14: 60 | F14: 1400 | G14: 84000
C15: Hyderabad | D15: 6 | E15: 35 | F15: 1550 | G15: 54250
C16: Ahmedabad | D16: 7 | E16: 42 | F16: 1480 | G16: 62160
C17: Pune | D17: 8 | E17: 48 | F17: 1530 | G17: 73440
C18: Jaipur | D18: 9 | E18: 38 | F18: 1680 | G18: 63840
C19: Lucknow | D19: 10 | E19: 30 | F19: 1600 | G19: 48000
C20: Chandigarh | D20: 11 | E20: 32 | F20: 1550 | G20: 49600
C21: Indore | D21: 12 | E21: 25 | F21: 1700 | G21: 42500
... C59: Chennai | D59: 50 | E59: 35 | F59: 1410 | G59: 49350
E61: Arranging the Data
C63: City | D63: Item Number | E63: Quantity | F63: Price (per product, ₹) | G63: Amount (₹)
C64: Ahmedabad | D64: 7 | E64: 42 | F64: 1480 | G64: 62160
C65: Ahmedabad | D65: 22 | E65: 42 | F65: 1490 | G65: 62580
C66: Ahmedabad | D66: 37 | E66: 40 | F66: 1500 | G66: 60000
C67: Ahmedabad Total | G67: =SUBTOTAL(9,G64:G66) -> 184740
C68: Bangalore | D68: 3 | E68: 55 | F68: 1450 | G68: 79750
C69: Bangalore | D69: 18 | E69: 50 | F69: 1480 | G69: 74000
C70: Bangalore | D70: 33 | E70: 58 | F70: 1470 | G70: 85460
C71: Bangalore | D71: 48 | E71: 45 | F71: 1490 | G71: 67050
C72: Bangalore Total | G72: =SUBTOTAL(9,G68:G71) -> 306260
C73: Chandigarh | D73: 11 | E73: 32 | F73: 1550 | G73: 49600
C74: Chandigarh | D74: 26 | E74: 30 | F74: 1560 | G74: 46800
C75: Chandigarh | D75: 41 | E75: 22 | F75: 1570 | G75: 34540
C76: Chandigarh Total | G76: =SUBTOTAL(9,G73:G75) -> 130940
C77: Chennai | D77: 5 | E77: 60 | F77: 1400 | G77: 84000
C78: Chennai | D78: 20 | E78: 52 | F78: 1420 | G78: 73840
C79: Chennai | D79: 35 | E79: 50 | F79: 1430 | G79: 71500
C80: Chennai | D80: 50 | E80: 35 | F80: 1410 | G80: 49350
C81: Chennai Total | G81: =SUBTOTAL(9,G77:G80) -> 278690
C82: Delhi | D82: 2 | E82: 45 | F82: 1600 | G82: 72000
C83: Delhi | D83: 17 | E83: 60 | F83: 1580 | G83: 94800
C84: Delhi | D84: 32 | E84: 55 | F84: 1590 | G84: 87450
...

Sheet CONDITIONAL FORMATTING
D2: 6 MODULE
D4: Conditional formatting | P4: POINTS TO BE NOTED
B6: QUESTION
B7: You have a spreadsheet with sales data for the first 10 months of a year. The data is in a table format with the months in column Months and the sales figures in column Sale
B8: You want to apply conditional formatting to the sales figures to highlight the following: | P8: can use multiple conditional on particular data
P9: to make a filter that only this text or nujmber should be contain we can use data validation
B10: 1. Sales figures greater than 10,000 should be highlighted in green. | P10: we used reference in workbook Q8
B11: 2. Sales figures between 5,000 and 10,000 should be highlighted in yellow.
B12: 3. Sales figures less than 5,000 should be highlighted in red.
D14: Conditional formating
C16: Month | D16: shoes name | E16: Qt | F16: Sale [INR] | H16: Month | I16: shoes name | J16: Qt | K16: Sale [INR]
C17: Jan | D17: Nike | E17: 150 | F17: 35000 | H17: Jan | I17: Nike | J17: 150 | K17: 35000
C18: Jan | D18: Adidas | E18: 120 | F18: 25000 | H18: Jan | I18: Adidas | J18: 120 | K18: 25000
C19: Jan | D19: Puma | E19: 80 | F19: 12000 | H19: Jan | I19: Puma | J19: 80 | K19: 12000
C20: Jan | D20: Reebok | E20: 100 | F20: 20000 | H20: Jan | I20: Reebok | J20: 100 | K20: 7880
C21: Jan | D21: Asics | E21: 140 | F21: 32000 | H21: Jan | I21: Asics | J21: 140 | K21: 32000
C22: Jan | D22: Skechers | E22: 110 | F22: 18000 | H22: Jan | I22: Skechers | J22: 110 | K22: 18000
C23: Jan | D23: New Balance | E23: 70 | F23: 10000 | H23: Jan | I23: New Balance | J23: 70 | K23: 10000
C24: Jan | D24: Under Armour | E24: 90 | F24: 15500 | H24: Jan | I24: Under Armour | J24: 90 | K24: 15500
C25: Jan | D25: Converse | E25: 130 | F25: 28000 | H25: Jan | I25: Converse | J25: 130 | K25: 28000
C26: Jan | D26: Vans | E26: 60 | F26: 8000 | H26: Jan | I26: Vans | J26: 60 | K26: 8000
C27: Feb | D27: Nike | E27: 160 | F27: 38000 | H27: Feb | I27: Nike | J27: 160 | K27: 38000
C28: Feb | D28: Adidas | E28: 130 | F28: 26000 | H28: Feb | I28: Adidas | J28: 130 | K28: 26000
... C66: May | D66: Vans | E66: 80 | F66: 12000 | H66: May | I66: Vans | J66: 80 | K66: 12000
C69: workbook Q1
C71: Date | D71: Product | E71: Region | F71: Amount | H71: change in product | I71: Dairy
C72: 43930 | D72: Dairy | E72: Denmark | F72: 1148 | H72: change in Amount | I72: 300
C73: 43977 | D73: Produce | E73: Denmark | F73: 1530
C74: 43806 | D74: Produce | E74: Denmark | F74: 1423.5
E75: Denmark Total | F75: =SUBTOTAL(9,F72:F74) -> 4101.5
C76: 43774 | D76: Dairy | E76: Finland | F76: 192.1
C77: 44024 | D77: Dairy | E77: Finland | F77: 351
C78: 43984 | D78: Grain | E78: Finland | F78: 560.4
E79: Finland Total | F79: =SUBTOTAL(9,F76:F78) -> 1103.5
C80: 44073 | D80: Dairy | E80: Germany | F80: 470
C81: 44038 | D81: Dairy | E81: Germany | F81: 17.4
C82: 44098 | D82: Grain | E82: Germany | F82: 1405
C83: 44134 | D83: Grain | E83: Germany | F83: 470
C84: 44069 | D84: Grain | E84: Germany | F84: 17.4
C85: 44019 | D85: Grain | E85: Germany | F85: 747
...

Sheet ANALYSIS
C2: 7 MODULE
C4: What if Analysis fn | K4: POINTS TO BE NOTED
B7: Question: | K7: data(what if analysis)
K8: to convert in 50 to 5,00,000 ( multiple formula with desire zeroes )
B9: You are managing a car showroom and have data about the cost, selling price, and units sold for different car brands over the past five months. | K9: for comma = used number format (use separator)
B10: You want to analyze how changes in costs and selling prices affect your total profit. The data is organized as follows:
K11: Face value formula
K12: FV(percentage/12, years*12, - monthly inv, - intial inv)
B13: Month | C13: Car Brand | D13: Cost (₹ Lakhs) | E13: Selling Price (₹ Lakhs) | F13: Units Sold | G13: Total Profit (₹ Lakhs)
B14: Jan | C14: Toyota | D14: 15 | E14: 20 | F14: 10 | G14: =E14*F14-D14*F14 -> 50
B15: Jan | C15: Honda | D15: 12 | E15: 18 | F15: 8 | G15: =E15*F15-D15*F15 -> 48
B16: Jan | C16: Ford | D16: 14 | E16: 19 | F16: 7 | G16: =E16*F16-D16*F16 -> 35
B17: Jan | C17: BMW | D17: 25 | E17: 35 | F17: 5 | G17: =E17*F17-D17*F17 -> 50
B18: Jan | C18: Audi | D18: 30 | E18: 45 | F18: 4 | G18: =E18*F18-D18*F18 -> 60
B19: Feb | C19: Toyota | D19: 15 | E19: 21 | F19: 12 | G19: =E19*F19-D19*F19 -> 72
B20: Feb | C20: Honda | D20: 12 | E20: 19 | F20: 9 | G20: =E20*F20-D20*F20 -> 63
B21: Feb | C21: Ford | D21: 14 | E21: 20 | F21: 6 | G21: =E21*F21-D21*F21 -> 36
B22: Feb | C22: BMW | D22: 25 | E22: 36 | F22: 6 | G22: =E22*F22-D22*F22 -> 66
B23: Feb | C23: Audi | D23: 30 | E23: 46 | F23: 5 | G23: =E23*F23-D23*F23 -> 80
B24: Mar | C24: Toyota | D24: 16 | E24: 22 | F24: 11 | G24: =E24*F24-D24*F24 -> 66
B25: Mar | C25: Honda | D25: 13 | E25: 20 | F25: 10 | G25: =E25*F25-D25*F25 -> 70
... B38: May | C38: Audi | D38: 33 | E38: 49 | F38: 8 | G38: =E38*F38-D38*F38 -> 128
B40: Tasks:
B42: 1. Calculate Total Profit: Use the formula for each row to calculate the total profit for each car brand in each month.
B44: 2. Scenario Analysis: Perform a scenario analysis to see how changes in the selling price of Toyota cars affect the total profit in the month of January. Assume three scenarios:
B45: Best case: Selling price increases by 10%.
B46: Most likely case: Selling price remains the same.
B47: Worst case: Selling price decreases by 10%.
B49: 3. Goal Seek Analysis: Use the Goal Seek tool to determine what the selling price of Audi cars should be in May to achieve a total profit of ₹200 lakhs for that month.
D52: Solving the Question
B53: Case 2
B54: Scenario | C54: Car Brand | D54: Cost (₹ Lakhs) | E54: Selling Price (₹ Lakhs) | F54: Units Sold | G54: Total Profit (₹ Lakhs)
B55: best case | C55: Toyota | D55: 15 | E55: 22 | F55: 10 | G55: =(E55*F55-D55*F55)*10000 -> 700000
B56: likely case | C56: Toyota | D56: 15 | E56: 20 | F56: 10 | G56: =(E56*F56-D56*F56)*10000 -> 500000
B57: worst case | C57: Toyota | D57: 15 | E57: 18 | F57: 10 | G57: =(E57*F57-D57*F57)*10000 -> 300000
B60: Case 3
B61: Month | C61: Car Brand | D61: Cost (₹ Lakhs) | E61: Selling Price (₹ Lakhs) | F61: Units Sold | G61: Total Profit (₹ Lakhs)
B62: Jan | C62: Toyota | D62: 15 | E62: 20 | F62: 10 | G62: =(E62*F62-D62*F62)*10000 -> 500000
B63: Jan | C63: Honda | D63: 12 | E63: 18 | F63: 8 | G63: =(E63*F63-D63*F63)*10000 -> 480000
B64: Jan | C64: Ford | D64: 14 | E64: 19 | F64: 7 | G64: =(E64*F64-D64*F64)*10000 -> 350000
...

Sheet COLUMN CHART
B2: 8 MODULE
B4: CHARTS
I5: COLUMN CHART
A7: Q1) | B7: Can you create a column chart that displays the quarterly number of shoes sold and the sales for Nike across different regions.
B8: (e.g., North America, Europe, Asia Pacific, Latin America, Middle East) for the year 2023?"
B11: Region | C11: Q1 Sales ($) | D11: Q2 Sales ($) | E11: Q3 Sales ($) | F11: Q4 Sales ($)
B12: North America | C12: 50000 | D12: 55000 | E12: 60000 | F12: 65000
B13: Europe | C13: 40000 | D13: 45000 | E13: 47000 | F13: 50000
B14: Asia Pacific | C14: 35000 | D14: 37000 | E14: 39000 | F14: 42000
B15: Latin America | C15: 20000 | D15: 21000 | E15: 22000 | F15: 23000
B16: Middle East | C16: 15000 | D16: 16000 | E16: 17000 | F16: 18000
A31: Q3) | B31: "Can you create a stacked column chart that illustrates the monthly sales revenue and loss due to expiry of product
I32: STACKED COLUMN CHART
C34: Chocolate company Data
B36: Month | C36: Sales Revenue | D36: loss due to (expired)
B37: January | C37: 50000 | D37: 10000
B38: February | C38: 55000 | D38: 9000
B39: March | C39: 60000 | D39: 7500
B40: April | C40: 65000 | D40: 12500
B41: May | C41: 70000 | D41: 11000
B42: June | C42: 75000 | D42: 10000
B43: July | C43: 80000 | D43: 9000
B44: August | C44: 85000 | D44: 15000
B45: September | C45: 90000 | D45: 14000
B46: October | C46: 95000 | D46: 12500
B47: November | C47: 100000 | D47: 11000
B48: December | C48: 105000 | D48: 10000

Sheet LINE CHART
B2: 8 MODULE
B4: CHARTS
G6: LINE CHART
A8: Q1) | B8: Create a line chart that illustrates the trends in annual supply, demand, and gold prices for the period from 2014 to 2023?"
B10: Year | C10: Supply (tons) | D10: Demand (tons)
B11: 2014 | C11: 2800 | D11: 3000
B12: 2015 | C12: 2750 | D12: 3100
B13: 2016 | C13: 2900 | D13: 3200
B14: 2017 | C14: 3000 | D14: 3300
B15: 2018 | C15: 2950 | D15: 3350
B16: 2019 | C16: 3100 | D16: 3400
B17: 2020 | C17: 3200 | D17: 3450
B18: 2021 | C18: 3150 | D18: 3500
B19: 2022 | C19: 3300 | D19: 3550
B20: 2023 | C20: 3350 | D20: 3600
G31: BAR CHART
A33: Q2) | B33: Make a bar chart of most games sold in gaming industries over 50 decades of time period.
B35: Rank | C35: Title | D35: Units Sold (Million)
B36: #1 | C36: Wii Sports | D36: 82.65
B37: #2 | C37: Super Mario Bros. | D37: 40.24
B38: #3 | C38: Mario Kart Wii | D38: 35.98
B39: #4 | C39: Wii Sport Resort | D39: 32.9
B40: #5 | C40: Pokémon R/G/B | D40: 31.37
B41: #6 | C41: Tetris | D41: 30.26
B42: #7 | C42: New Super Mario Bros. | D42: 29.85
B43: #8 | C43: Wii Play | D43: 28.92
B44: #9 | C44: New Super Mario Bros | D44: 28.51
B45: #10 | C45: Duck Hunt | D45: 28.31
B46: #11 | C46: Nintendogs | D46: 24.68
B47: #12 | C47: Mario Kart DS | D47: 23.26
... B55: #20 | C55: Brain Age | D55: 20.16
G76: SCATTER LINE CHART
A78: Q3) | B78: Make a line chart of daily temperature of Delhi city 2024 9minimum and maimum temperature)
B80: DATE | C80: MIN TEMPERATURE | D80: MAX TEMPERATURE
B81: 45345 | C81: 26.2 | D81: 7.6
B82: 45346 | C82: 24.4 | D82: 8.7
B83: 45347 | C83: 24.6 | D83: 8.3
B84: 45348 | C84: 27 | D84: 9.9
B85: 45349 | C85: 25 | D85: 12.3
B86: 45350 | C86: 25.4 | D86: 10.7
...

Sheet PIE CHART
B2: 8 MODULE
B4: CHARTS
I6: PIE CHART
A8: Q1) | B8: Tanishq Jewellers reported their annual profits for five different types of ornaments. The profits are as follows. Make a pie chart of this report
D10: Yearly Profits of Tanishq Jewellers (in crores)
B12: YEAR | C12: Gold Necklaces | D12: Diamond Rings | E12: Silver Bracelets | F12: Platinum Earrings | G12: Gemstone Pendants
B13: 2023 | C13: 211000000 | D13: 320500000 | E13: 66000000 | F13: 49500000 | G13: 83000000
I37: WATERFALL CHART
A40: Q2) | B40: Growmore Trading reported their monthly returns for the year ,make a visual representation of it in waterfall chart
B42: Month | C42: Return (₹ lakhs)
B43: January | C43: 2500000
B44: February | C44: -1500000
B45: March | C45: 2000000
B46: April | C46: -1000000
B47: May | C47: 3000000
B48: June | C48: -2500000
B49: July | C49: 1800000
B50: August | C50: -1200000
B51: September | C51: 2200000
B52: October | C52: -2000000
B53: November | C53: 2800000
B54: December | C54: -3000000
B56: Visualize these monthly returns using appropriate tools to analyze Growmore Trading's performance throughout the year.

Sheet TEXT FUNCTIONS
C2: 9 MODULE
C4: TEXT FUNCTIONS | L4: POINTS TO BE NOTED
L6: TRIM FN - trim the space from cell
C7: BASIC UNDERSTANDING OF FUNCTIONS | L7: CLEAN - non printable characters
C8: Alexander James Smith | L8: IFERROR - write error whatever we wanted or true or false
C9: functions | D9: USED | L9: REPT - rept the same thing again and again
C10: LEFT | D10: =LEFT(C8,9) -> Alexander | L10: SUBSTITUE - substitue is case senstive
C11: RIGHT | D11: =RIGHT(C8,3) -> ith | L11: LEN - length of txt or number
C12: MID | D12: =MID(C8,11,1) -> J | L12: Evaluate fn in formulas ribbion
C13: FIND | D13: =FIND(" ",C8) -> 10 | L13: bahtext means curreny of thailand
C14: SEARCH | D14: =SEARCH("j",C8) -> 11 | L14: T Fnc used whether data is text or not ( if it is text it show )or (if not empty cell will come)
C15: TODAY | D15: =TODAY() -> 45722 | L15: exact used for find that both text are same or not, and it’s a case sensitive
C16: NOW | D16: =NOW() -> 45722.797 | L16: char help to find charcter of selected cell
C17: CONCATENATE | D17: =CONCATENATE(C8,D13) -> Alexander James Smith10 | L17: use syntax in text function (" ")
C18: FORMULATEXT | D18: =_xlfn.FORMULATEXT(D10) -> =LEFT(C8,9) | L18: we use (INT) fn in age to get round number in age
C19: UPPER | D19: =UPPER(C8) -> ALEXANDER JAMES SMITH
C20: LOWER | D20: =LOWER(C8) -> alexander james smith
C21: PROPER | D21: =PROPER(C8) -> Alexander James Smith
C22: LEN | D22: =LEN(C8) -> 21
C23: REPT | D23: =REPT(D22,5) -> 2121212121
C24: SUBSTITUTE | D24: =SUBSTITUTE(C8,"Alexander","frankrut") -> frankrut James Smith
C25: REPLACE | D25: =REPLACE(C8,1,3,"Robo") -> Roboxander James Smith
C26: inferror fn | D26: =IFERROR(D13<2,) -> FALSE
C27: dollar | D27: =DOLLAR(49,2) -> ₹ 49.00
C28: fixed | D28: =FIXED(34455,1,FALSE) -> 34,455.0
C29: numbervalue | D29: =_xlfn.NUMBERVALUE(D27) -> 49
C30: text | D30: =TEXT(D15,"dd mm yyyy") -> 06 03 2025
C31: t | D31: =T(D27) -> ₹ 49.00
C32: bahttext | D32: =BAHTTEXT(345) -> สามร้อยสี่สิบห้าบาทถ้วน
A33: j | C33: code | D33: =CODE(D28) -> 51
C34: value | D34: =VALUE(D31) -> 49
C35: char | D35: =CHAR(D34) -> 1
C36: exact | D36: =EXACT(E34,D11) -> FALSE
C39: Trim fn
C40: name | D40: Rahul
C41: len | D41: =LEN(D40) -> 13
C42: trim fn | D42: =TRIM(D40) -> Rahul
C43: len | D43: =LEN(D42) -> 5
E46: SOLVE THIS TABLE USING FORMULAS ONLY
B49: name | C49: first space | D49: Second space | E49: lens | F49: difference | G49: first name | H49: Middle name | I49: last name
...

Sheet MATHEMATICAL FUNCTIONS
B3: 10 MODULE
B5: MATHEMATICAL FUNCTIONS | M5: Points to be Noted
M8: count fn only counts numericals numbers
B9: BASIC UNDERSTANDING | M9: countif used for giving conditions (only 1)
B10: Sample Data 1 | F10: SAMPLE DATA 2 | M10: countifs used for giving two conditions
B11: FUNCTIONS | C11: 206 | M11: counta counts text and numbers both and aslo count empty cell in multiple columns
C12: 41 | G12: 164
C13: 185 | G13: b | M13: sum fn only sums numericals numbers
C14: 132 | G14: 423 | M14: sumif used for giving conditions (only 1)
C15: 145 | G15: 373 | M15: sumifs used for giving two conditions
C16: 238
C17: 34 | G17: 415 | M17: power used to find exponential power of numbers, ex
C18: 197 | G18: 61 | M18: POWER(2, 3) results in 8 (because 2x2x2=8)
C19: 241 | G19: 271
C20: 173 | G20: 32 | M20: Sqrt = help to find the square of a number ,ex
C21: 146 | G21: 238 | M21: sqrt(9) = 3
B22: SUM | C22: =SUM(C11:C21) -> 1738 | F22: Count | G22: =COUNT(G12:G21) -> 8
B23: AVERAGE | C23: =AVERAGE(C11:C21) -> 158 | F23: CountA | G23: =COUNTA(G12:G21) -> 9 | M23: mean = average
B24: MIN | C24: =MIN(C11:C21) -> 34 | F24: SUM | G24: =SUM(G12:G21) -> 1977 | M24: median = The middle value in a list of numbers
B25: MAX | C25: =MAX(C11:C21) -> 241 | F25: AVERAGE | G25: =AVERAGE(G12:G21) -> 247.125 | M25: mode = The number that appears most frequently in a list.
M26: {=MODE.SNGL(range) (for a single mode) or =MODE.MULT(range) for multiples}
M28: we should always write text in inverted commas
M30: DGET = number error(if answer have more than 1)
B35: Sample Data 3
B37: Team | C37: Points | D37: Date
B38: Team A | C38: 85 | D38: 45292
B39: Team B | C39: 90 | D39: 45293
B40: Team A | C40: 78 | D40: 45294
B41: Team C | C41: 92 | D41: 45292
B42: Team B | C42: 88 | D42: 45295
B43: Team A | C43: 80 | D43: 45296
B44: Team C | C44: 95 | D44: 45293
B45: Team B | C45: 86 | D45: 45294
B46: Team C | C46: 91 | D46: 45295
B49: Task
B50: 1. Calculate the total points scored by Team A.
B51: 2. Determine the total points scored by Team B between 2024-01-01 and 2024-01-03.
B52: 3. Count the number of entries where Team C has scored points.
B53: 4. Count the number of entries for Team A between 2024-01-01 and 2024-01-05.
B54: 5. Find the average points scored by Team B.
...

Sheet LOGICAL FUNCTIONS
B2: 11 MODULE
B4: LOGICAL & DATE/TIME FUNCTIONS
B7: LOGICAL FUNCTIONS
B10: Sample Data:
B12: Employee | C12: Hours Worked | D12: Project Deadline Met | E12: Overtime Hours | F12: Department
B13: John | C13: 40 | D13: Yes | E13: 5 | F13: Sales
B14: Alice | C14: 35 | D14: No | E14: 2 | F14: Marketing
B15: Bob | C15: 45 | D15: Yes | E15: 10 | F15: IT
B16: Carol | C16: 50 | D16: Yes | E16: 0 | F16: IT
B17: Dave | C17: 30 | D17: No | E17: 8 | F17: Sales
B18: Eve | C18: 38 | D18: Yes | E18: 4 | F18: Marketing
B19: Frank | C19: 42 | D19: No | E19: 6 | F19: IT
B22: Task Number | C22: Task Description
B23: 1 | C23: Check if the employee worked more than 40 hours.
B24: 2 | C24: Determine if an employee worked more than 40 hours and met the project deadline.
B25: 3 | C25: Check if an employee worked more than 40 hours and has more than 5 overtime hours.
B26: 4 | C26: Determine if an employee either worked more than 40 hours or has more than 5 overtime hours.
B27: 5 | C27: Check if an employee worked more than 40 hours and is in the IT department.
B28: 6 | C28: Determine if an employee worked more than 40 hours or is in the Marketing department.
B29: 7 | C29: Check if an employee did not meet the project deadline
B32: TASK NO | C32: 1 | D32: 2 | E32: 3 | F32: 4 | G32: 5 | H32: 6 | I32: 7
B33: FUNCTIONS USED | C33: if condition | D33: NESTED IF | E33: AND | F33: OR | G33: IF WITH AND | H33: IF WITH OR | I33: IF WITH NOT
B34: 1 | C34: =IF($C13>40,"YES","NO") -> NO | D34: =IF($C13>40,"YES",IF(D13="YES","MET","NOT MET")) -> MET | E34: =AND(C13>40,E13>5) -> FALSE | F34: =IF(OR(C13>40,E13>5),"YES","NO") -> NO | G34: =IF(AND(C13>40,F13="IT"),"YES","NO") -> NO | H34: =IF(OR(C13>40,F13="Marketing"),"Yes","No") -> No | I34: =IF(NOT(D13="yes"),"met","not met") -> not met
B35: 2 | C35: =IF($C14>40,"YES","NO") -> NO | D35: =IF($C14>40,"YES",IF(D14="YES","MET","NOT MET")) -> NOT MET | E35: =AND(C14>40,E14>5) -> FALSE | F35: =IF(OR(C14>40,E14>5),"YES","NO") -> NO | G35: =IF(AND(C14>40,F14="IT"),"YES","NO") -> NO | H35: =IF(OR(C14>40,F14="Marketing"),"Yes","No") -> Yes | I35: =IF(NOT(D14="yes"),"met","not met") -> met
B36: 3 | C36: =IF($C15>40,"YES","NO") -> YES | D36: =IF($C15>40,"YES",IF(D15="YES","MET","NOT MET")) -> YES | E36: =AND(C15>40,E15>5) -> TRUE | F36: =IF(OR(C15>40,E15>5),"YES","NO") -> YES | G36: =IF(AND(C15>40,F15="IT"),"YES","NO") -> YES | H36: =IF(OR(C15>40,F15="Marketing"),"Yes","No") -> Yes | I36: =IF(NOT(D15="yes"),"met","not met") -> not met
B37: 4 | C37: =IF($C16>40,"YES","NO") -> YES | D37: =IF($C16>40,"YES",IF(D16="YES","MET","NOT MET")) -> YES | E37: =AND(C16>40,E16>5) -> FALSE | F37: =IF(OR(C16>40,E16>5),"YES","NO") -> YES | G37: =IF(AND(C16>40,F16="IT"),"YES","NO") -> YES | H37: =IF(OR(C16>40,F16="Marketing"),"Yes","No") -> Yes | I37: =IF(NOT(D16="yes"),"met","not met") -> not met
B38: 5 | C38: =IF($C17>40,"YES","NO") -> NO | D38: =IF($C17>40,"YES",IF(D17="YES","MET","NOT MET")) -> NOT MET | E38: =AND(C17>40,E17>5) -> FALSE | F38: =IF(OR(C17>40,E17>5),"YES","NO") -> YES | G38: =IF(AND(C17>40,F17="IT"),"YES","NO") -> NO | H38: =IF(OR(C17>40,F17="Marketing"),"Yes","No") -> No | I38: =IF(NOT(D17="yes"),"met","not met") -> met
B39: 6 | C39: =IF($C18>40,"YES","NO") -> NO | D39: =IF($C18>40,"YES",IF(D18="YES","MET","NOT MET")) -> MET | E39: =AND(C18>40,E18>5) -> FALSE | F39: =IF(OR(C18>40,E18>5),"YES","NO") -> NO | G39: =IF(AND(C18>40,F18="IT"),"YES","NO") -> NO | H39: =IF(OR(C18>40,F18="Marketing"),"Yes","No") -> Yes | I39: =IF(NOT(D18="yes"),"met","not met") -> not met
B40: 7 | C40: =IF($C19>40,"YES","NO") -> YES | D40: =IF($C19>40,"YES",IF(D19="YES","MET","NOT MET")) -> YES | E40: =AND(C19>40,E19>5) -> TRUE | F40: =IF(OR(C19>40,E19>5),"YES","NO") -> YES | G40: =IF(AND(C19>40,F19="IT"),"YES","NO") -> YES | H40: =IF(OR(C19>40,F19="Marketing"),"Yes","No") -> Yes | I40: =IF(NOT(D19="yes"),"met","not met") -> met
B43: DATE & TIME FUNCTIONS
B46: Sample Data:
B48: Event | C48: Start Date | D48: End Date | E48: Start Time | F48: End Time | G48: text format
B49: Project Kickoff | C49: 45505 | D49: 45514 | E49: 0.375 | F49: 0.70833333 | G49: 01-08-2024
B50: Midterm Review | C50: 45519 | D50: 45520 | E50: 0.41666667 | F50: 0.625 | G50: 09:00:00
B51: Final Deadline | C51: 45534 | D51: 45537 | E51: 0.33333333 | F51: 0.75
B54: Task Number | C54: Task Description
B55: 1 | C55: Get Today’s Date
B56: 2 | C56: Get the Current Date and Time
B57: 3 | C57: Extract the Day from the Start Date of the Project Kickoff
B58: 4 | C58: Extract the Month from the Start Date of the Project Kickoff
...

Sheet DATABASE FUNCTIONS
C3: 12 MODULE
C5: DATABASE FUNCTIONS | Y5: Points to be Noted
Y7: XLOOKUP , SORTING IS NOT AVAILABLE IN OLDER VERSION
C8: Question 1
D9: 1 | E9: 2 | F9: 3 | G9: 4 | H9: 5 | I9: 6 | J9: 7 | Y9: lookup
C10: Product ID | D10: Phone Names | E10: Category | F10: Price | G10: Stock | H10: Supplier | I10: Rating | J10: Discount | Y10: lookup help to find data from selected zone
C11: 101 | D11: iPhone 13 | E11: Smartphones | F11: 799 | G11: 120 | H11: John Smith | I11: 4.5 | J11: 0.05 | Y11: it always give data to last selected cell (column,row)
C12: 102 | D12: Galaxy S21 | E12: Smartphones | F12: 699 | G12: 85 | H12: Jane Doe | I12: 4 | J12: 0.1 | Y12: it always check the data of first column/row of selected cell to give result
C13: 103 | D13: Pixel 6 | E13: Smartphones | F13: 599 | G13: 60 | H13: Michael Johnson | I13: 4.7 | J13: 0
C14: 104 | D14: OnePlus 9 | E14: Smartphones | F14: 729 | G14: 150 | H14: Emily Davis | I14: 4.2 | J14: 0.15 | Y14: limitation
C15: 105 | D15: Redmi Note 10 | E15: Smartphones | F15: 199 | G15: 200 | H15: Chris Brown | I15: 4.8 | J15: 0.2 | Y15: if the value came above the desire value , it give its previous value of data
C16: 106 | D16: Moto G Power | E16: Smartphones | F16: 249 | G16: 100 | H16: Sarah Wilson | I16: 4.3 | J16: 0.05
C17: 107 | D17: Xperia 5 III | E17: Smartphones | F17: 899 | G17: 130 | H17: Daniel Martinez | I17: 4.1 | J17: 0.1 | Y17: solution
C18: 108 | D18: Nokia 8.3 | E18: Smartphones | F18: 479 | G18: 75 | H18: Laura White | I18: 4.4 | J18: 0.07 | Y18: data should always in ascending or correct form to get right result
C19: 109 | D19: LG Velvet | E19: Smartphones | F19: 599 | G19: 80 | H19: Robert Harris | I19: 4 | J19: 0.12
C20: 110 | D20: Huawei P30 | E20: Smartphones | F20: 649 | G20: 110 | H20: Jessica Clark | I20: 4.5 | J20: 0.08 | Y20: Vlookup - Vertical lookup (|)
C21: 111 | D21: ZTE Axon 20 | E21: Smartphones | F21: 399 | G21: 90 | H21: David Lewis | I21: 4.2 | J21: 0.06 | Y21: Hlookup - Horizontal lookup (-----)
C22: 112 | D22: HTC U12+ | E22: Smartphones | F22: 599 | G22: 60 | H22: Angela Robinson | I22: 4.1 | J22: 0.1 | Y22: 0 - Exact value ( if data did not have that value it give us error)
C23: 113 | D23: Oppo Find X3 | E23: Smartphones | F23: 799 | G23: 95 | H23: Thomas Walker | I23: 4.3 | J23: 0.04 | Y23: 1- approx value ( it give us previous data value that is smaller than our desired value)
C24: 114 | D24: Vivo X60 | E24: Smartphones | F24: 699 | G24: 140 | H24: Amy Hall | I24: 4.6 | J24: 0.03
C25: 115 | D25: Asus ROG Phone 5 | E25: Smartphones | F25: 999 | G25: 50 | H25: Steven Allen | I25: 4.8 | J25: 0 | Y25: Xlookup ( most useful and smartest lookup available in 2021 version)
C26: 116 | D26: Realme GT | E26: Smartphones | F26: 399 | G26: 120 | H26: Ashley Young | I26: 4.2 | J26: 0.05
C27: 117 | D27: Honor 50 | E27: Smartphones | F27: 549 | G27: 105 | H27: Brian King | I27: 4 | J27: 0.07 | Y27: INDEX and MATCH
C28: 118 | D28: BlackBerry Key2 | E28: Smartphones | F28: 699 | G28: 45 | H28: Karen Wright | I28: 4.7 | J28: 0.05 | Y28: Index function help to get the desire data from selected array
C29: 119 | D29: Fairphone 3+ | E29: Smartphones | F29: 469 | G29: 130 | H29: Edward Scott | I29: 4.4 | J29: 0.02 | Y29: Match function help to find the position of desired data
C30: 120 | D30: Palm Phone | E30: Smartphones | F30: 349 | G30: 60 | H30: Lisa Adams | I30: 4.5 | J30: 0.15
C32: VLOOKUP Questions
C34: 1. Using the above dataset, find the price of the iPhone 13 using the VLOOKUP function
C35: 2. Find the stock available for the Pixel 6 using the VLOOKUP function.
C36: 3. Determine the supplier for the Galaxy S21 using the VLOOKUP function.
C37: 4. Find the discount percentage for the Redmi Note 10 using the VLOOKUP function.
C38: 5. Retrieve the rating for the OnePlus 9 using the VLOOKUP function.
C39: 6. Find the price of the Nokia 8.3 using the VLOOKUP function.
C40: 7. Determine the supplier for the Xperia 5 III using the VLOOKUP function.
C41: 8. Retrieve the stock available for the LG Velvet using the VLOOKUP function.
C42: 9. Find the rating for the Oppo Find X3 using the VLOOKUP function.
C43: 10. Determine the discount for the Moto G Power using the VLOOKUP function.
B46: 1 | C46: Product ID | D46: 101 | E46: 102 | F46: 103 | G46: 104 | H46: 105 | I46: 106 | J46: 107 | K46: 108 | L46: 109 | M46: 110 | N46: 111 | O46: 112 | P46: 113 | Q46: 114 | R46: 115 | S46: 116 | T46: 117 | U46: 118 | V46: 119 | W46: 120
B47: 2 | C47: Phone Names | D47: iPhone 13 | E47: Galaxy S21 | F47: Pixel 6 | G47: OnePlus 9 | H47: Redmi Note 10 | I47: Moto G Power | J47: Xperia 5 III | K47: Nokia 8.3 | L47: LG Velvet | M47: Huawei P30 | N47: ZTE Axon 20 | O47: HTC U12+ | P47: Oppo Find X3 | Q47: Vivo X60 | R47: Asus ROG Phone 5 | S47: Realme GT | T47: Honor 50 | U47: BlackBerry Key2 | V47: Fairphone 3+ | W47: Palm Phone
B48: 3 | C48: Category | D48: Smartphones | E48: Smartphones | F48: Smartphones | G48: Smartphones | H48: Smartphones | I48: Smartphones | J48: Smartphones | K48: Smartphones | L48: Smartphones | M48: Smartphones | N48: Smartphones | O48: Smartphones | P48: Smartphones | Q48: Smartphones | R48: Smartphones | S48: Smartphones | T48: Smartphones | U48: Smartphones | V48: Smartphones | W48: Smartphones
...

Sheet FUNCTIONS PRACTICE
B2: Question 1
B4: Questions: | K4: Answer
K5: 1 | L5: product Id | M5: =LOOKUP("00000014",B31:B72,L31:L72) -> Karen N. Harris
B6: 1. Text Extraction: | L6: "00000014" | M6: =LEFT(M5,FIND(" ",M5)) -> Karen
B7: Extract the first and last name from the Supplier Name column for the product with Product ID "00000014". | M7: =TRIM(RIGHT(M5,LEN(M5)-(FIND(" ",M5)+1)-1)) -> Harris
B8: 2. Date and Time Formatting:
B9: Display the current date and time in the formats "MM/DD/YYYY" and "HH:MM | K9: 2 | L9: current day and time | M9: format mm/dd/yyyy
B10: " respectively. | L10: =NOW() -> 45722.797 | M10: =(TEXT(L10,"mm dd yyyy")) -> 03 06 2025
B11: 3. Sales Analysis:
B12: Calculate the total, average, minimum, and maximum sales amounts. | K12: 3 | L12: total | M12: =SUM('FUNCTIONS PRACTICE'!$E$31:$E$72) -> 36650
B13: Determine the number of products with a sales amount greater than $1000. | L13: average | M13: =AVERAGE('FUNCTIONS PRACTICE'!$E$31:$E$72) -> 872.61905
B14: Count the number of products with a rating of 5. | L14: min | M14: =MIN('FUNCTIONS PRACTICE'!$E$31:$E$72) -> 300
B15: 4. Lookup: | L15: max | M15: =MAX('FUNCTIONS PRACTICE'!$E$31:$E$72) -> 1800
B16: Find the sales amount for the product with Product ID "00000018".
B17: 5. Categorization: | L17: no of products | M17: =COUNTIF(E31:E72,">=1000") -> 15
B18: Create a new column that categorizes products as "High Discount" if the discount is greater than 15% and "Low Discount" otherwise. | L18: no of products, rating 5 | M18: =COUNTIF(I31:I72,">=5") -> 20
B19: 6. Text Manipulation:
B20: Convert the product names to uppercase, lowercase, and proper case. | K20: 4 | L20: sales amount | M20: =VLOOKUP("00000018",B31:AA72,4,0) -> 500
B21: 7. Length and Replacement:
B22: Find the length of the product name for the product with Product ID "00000025". | K22: 7 | L22: len
B23: Modify customer feedback to standardize phrases, such as replacing "Good" with "Excellent". | L23: "00000025" | M23: =LEN(INDEX(C31:C72,MATCH("00000025",B31:B72,0),)) -> 11
B24: 8. Additional Tasks:
B25: Calculate the total sales for all products in the West region. | K25: 8 | L25: total sales in west region | M25: =SUMIF(B31:V72,LOOKUP("west",J31:J71,E31:E72)) -> 3500
B26: Format the sales date of the product with Product ID "00000027" in "DD-MMM-YYYY" format. | L26: =LOOKUP("00000027",B31:B72,G31:G72) -> 03/14/2023 | M26: =TEXT(L26,"mmm dd yyyy") -> 03/14/2023
X29: Ans 6 | AA29: Ans 5
B30: Product ID | C30: Product Name | D30: Category | E30: Sales Amount ($) | F30: Number of Units Sold | G30: Sales Date | H30: Customer Feedback | I30: Rating | J30: Region | K30: Discount (%) | L30: Supplier Name | M30: Warranty Period (months) | N30: Return Rate (%) | O30: Customer DOB | P30: Sales Channel | Q30: Inventory Level | R30: Shipping Cost ($) | S30: Payment Method | T30: Store Location | U30: Marketing Spend ($) | V30: Promotion Used | X30: upper case(P) | Y30: Lower case(P) | Z30: Proper case(P) | AA30: Discount
B31: 00000001 | C31: iPhone 13 Pro | D31: Electronics | E31: 1200 | F31: 50 | G31: 01/15/2023 | H31: Excellent product | I31: 5 | J31: East | K31: 10 | L31: John A. Smith | M31: 12 | N31: 2 | O31: 32640 | P31: Online | Q31: High | R31: 20 | S31: Credit Card | T31: New York | U31: 2000 | V31: Black Friday | X31: =UPPER(C31) -> IPHONE 13 PRO | Y31: =LOWER(X31) -> iphone 13 pro | Z31: =PROPER(Y31) -> Iphone 13 Pro | AA31: =IF(K31>=0.15*100,"High Discount","Low Discount") -> Low Discount
B32: 00000002 | C32: OnePlus 8T | D32: Electronics | E32: 950 | F32: 25 | G32: 01/30/2023 | H32: Fast and smooth | I32: 5 | J32: North | K32: 15 | L32: Richard T. Wright | M32: 18 | N32: 1 | O32: 34515 | P32: Online | Q32: Medium | R32: 20 | S32: Debit Card | T32: Washington | U32: 1100 | V32: Holiday Sale | X32: =UPPER(C32) -> ONEPLUS 8T | Y32: =LOWER(X32) -> oneplus 8t | Z32: =PROPER(Y32) -> Oneplus 8T | AA32: =IF(K32>=0.15*100,"High Discount","Low Discount") -> High Discount
B33: 00000003 | C33: Google Pixel 6 | D33: Electronics | E33: 900 | F33: 30 | G33: 45049 | H33: Good performance | I33: 4 | J33: North | K33: 15 | L33: James C. Williams | M33: 18 | N33: 3 | O33: 33793 | P33: Online | Q33: Low | R33: 15 | S33: Credit Card | T33: Chicago | U33: 1000 | V33: New Year Sale | X33: =UPPER(C33) -> GOOGLE PIXEL 6 | Y33: =LOWER(X33) -> google pixel 6 | Z33: =PROPER(Y33) -> Google Pixel 6 | AA33: =IF(K33>=0.15*100,"High Discount","Low Discount") -> High Discount
B34: 00000004 | C34: OnePlus 9 | D34: Electronics | E34: 750 | F34: 60 | G34: 01/20/2023 | H34: Excellent value | I34: 5 | J34: South | K34: 20 | L34: Patricia D. Brown | M34: 12 | N34: 4 | O34: 31092 | P34: In-Store | Q34: High | R34: 10 | S34: Debit Card | T34: Miami | U34: 800 | V34: End of Season Sale | X34: =UPPER(C34) -> ONEPLUS 9 | Y34: =LOWER(X34) -> oneplus 9 | Z34: =PROPER(Y34) -> Oneplus 9 | AA34: =IF(K34>=0.15*100,"High Discount","Low Discount") -> High Discount
B35: 00000005 | C35: Sony Xperia 5 | D35: Electronics | E35: 600 | F35: 55 | G35: 45262 | H35: Great display and performance | I35: 4 | J35: East | K35: 10 | L35: Aaron M. Lewis | M35: 12 | N35: 3 | O35: 32673 | P35: Online | Q35: Medium | R35: 20 | S35: Credit Card | T35: New York | U35: 850 | V35: Holiday Sale | X35: =UPPER(C35) -> SONY XPERIA 5 | Y35: =LOWER(X35) -> sony xperia 5 | Z35: =PROPER(Y35) -> Sony Xperia 5 | AA35: =IF(K35>=0.15*100,"High Discount","Low Discount") -> Low Discount
B36: 00000006 | C36: Samsung Galaxy S21 | D36: Electronics | E36: 1000 | F36: 45 | G36: 01/18/2023 | H36: Excellent screen quality | I36: 5 | J36: South | K36: 15 | L36: Julie M. Taylor | M36: 18 | N36: 2 | O36: 34689 | P36: In-Store | Q36: Medium | R36: 15 | S36: Debit Card | T36: Miami | U36: 1200 | V36: Flash Sale | X36: =UPPER(C36) -> SAMSUNG GALAXY S21 | Y36: =LOWER(X36) -> samsung galaxy s21 | Z36: =PROPER(Y36) -> Samsung Galaxy S21 | AA36: =IF(K36>=0.15*100,"High Discount","Low Discount") -> High Discount
B37: 00000006 | C37: Samsung Galaxy S21 | D37: Electronics | E37: 1000 | F37: 45 | G37: 01/18/2023 | H37: Excellent screen quality | I37: 5 | J37: South | K37: 15 | L37: Julie M. Taylor | M37: 18 | N37: 2 | O37: 34689 | P37: In-Store | Q37: Medium | R37: 15 | S37: Debit Card | T37: Miami | U37: 1200 | V37: Flash Sale | X37: =UPPER(C37) -> SAMSUNG GALAXY S21 | Y37: =LOWER(X37) -> samsung galaxy s21 | Z37: =PROPER(Y37) -> Samsung Galaxy S21 | AA37: =IF(K37>=0.15*100,"High Discount","Low Discount") -> High Discount
B38: 00000007 | C38: LG V60 ThinQ | D38: Electronics | E38: 950 | F38: 30 | G38: 44929 | H38: Great dual screen | I38: 4 | J38: North | K38: 5 | L38: Steven J. Lee | M38: 12 | N38: 2 | O38: 33428 | P38: Online | Q38: Medium | R38: 10 | S38: PayPal | T38: Chicago | U38: 1100 | V38: Spring Sale | X38: =UPPER(C38) -> LG V60 THINQ | Y38: =LOWER(X38) -> lg v60 thinq | Z38: =PROPER(Y38) -> Lg V60 Thinq | AA38: =IF(K38>=0.15*100,"High Discount","Low Discount") -> Low Discount
B39: 00000008 | C39: Nokia 8.3 | D39: Electronics | E39: 450 | F39: 50 | G39: 45201 | H39: Decent performance | I39: 3 | J39: South | K39: 5 | L39: Barbara H. Wilson | M39: 12 | N39: 4 | O39: 34197 | P39: In-Store | Q39: Medium | R39: 15 | S39: Debit Card | T39: Miami | U39: 500 | V39: Winter Sale | X39: =UPPER(C39) -> NOKIA 8.3 | Y39: =LOWER(X39) -> nokia 8.3 | Z39: =PROPER(Y39) -> Nokia 8.3 | AA39: =IF(K39>=0.15*100,"High Discount","Low Discount") -> Low Discount
B40: 00000009 | C40: Realme 8 Pro | D40: Electronics | E40: 700 | F40: 40 | G40: 02/15/2023 | H40: Good performance | I40: 4 | J40: West | K40: 20 | L40: Tina G. White | M40: 18 | N40: 3 | O40: 33716 | P40: In-Store | Q40: Low | R40: 25 | S40: Debit Card | T40: San Francisco | U40: 800 | V40: Winter Sale | X40: =UPPER(C40) -> REALME 8 PRO | Y40: =LOWER(X40) -> realme 8 pro | Z40: =PROPER(Y40) -> Realme 8 Pro | AA40: =IF(K40>=0.15*100,"High Discount","Low Discount") -> High Discount
B41: 00000010 | C41: Xiaomi Mi 11 | D41: Electronics | E41: 850 | F41: 40 | G41: 01/25/2023 | H41: Affordable and reliable | I41: 4 | J41: West | K41: 20 | L41: Elizabeth J. Taylor | M41: 24 | N41: 3 | O41: 35241 | P41: In-Store | Q41: Medium | R41: 25 | S41: PayPal | T41: Los Angeles | U41: 1200 | V41: Flash Sale | X41: =UPPER(C41) -> XIAOMI MI 11 | Y41: =LOWER(X41) -> xiaomi mi 11 | Z41: =PROPER(Y41) -> Xiaomi Mi 11 | AA41: =IF(K41>=0.15*100,"High Discount","Low Discount") -> High Discount
B42: 00000011 | C42: Xiaomi Mi Note 10 | D42: Electronics | E42: 700 | F42: 45 | G42: 03/18/2023 | H42: Good value for the price | I42: 4 | J42: South | K42: 15 | L42: Marcus J. Hall | M42: 12 | N42: 3 | O42: 32385 | P42: In-Store | Q42: High | R42: 15 | S42: PayPal | T42: Miami | U42: 900 | V42: Black Friday | X42: =UPPER(C42) -> XIAOMI MI NOTE 10 | Y42: =LOWER(X42) -> xiaomi mi note 10 | Z42: =PROPER(Y42) -> Xiaomi Mi Note 10 | AA42: =IF(K42>=0.15*100,"High Discount","Low Discount") -> High Discount
B43: 00000012 | C43: iPhone 12 Mini | D43: Electronics | E43: 1000 | F43: 45 | G43: 45263 | H43: Good performance | I43: 4 | J43: South | K43: 10 | L43: Sarah L. Jackson | M43: 12 | N43: 2 | O43: 34296 | P43: Online | Q43: Medium | R43: 20 | S43: PayPal | T43: Seattle | U43: 1100 | V43: End of Season Sale | X43: =UPPER(C43) -> IPHONE 12 MINI | Y43: =LOWER(X43) -> iphone 12 mini | Z43: =PROPER(Y43) -> Iphone 12 Mini | AA43: =IF(K43>=0.15*100,"High Discount","Low Discount") -> Low Discount
B44: 00000013 | C44: Xiaomi Mi Mix 4 | D44: Electronics | E44: 850 | F44: 45 | G44: 44928 | H44: Great display | I44: 4 | J44: North | K44: 10 | L44: Samuel W. Baker | M44: 12 | N44: 2 | O44: 32947 | P44: Online | Q44: Medium | R44: 20 | S44: PayPal | T44: Seattle | U44: 1000 | V44: Winter Sale | X44: =UPPER(C44) -> XIAOMI MI MIX 4 | Y44: =LOWER(X44) -> xiaomi mi mix 4 | Z44: =PROPER(Y44) -> Xiaomi Mi Mix 4 | AA44: =IF(K44>=0.15*100,"High Discount","Low Discount") -> Low Discount
...

Sheet POWER QUERY
B3: 11 MODULE
B5: POWER QUERY | K5: Points to be Noted
K7: data - new Query - select data from it
B8: Name | C8: Email | D8: Course | E8: Registration Date | F8: Fee Paid | G8: Name ID | H8: Session Start | I8: Payment Status | K8: I transform this data usiing power query
B9: Hailey Antcliff | C9: Hailey_Antcliff9757@yahoo.audio | D9: Leadership | E9: 44909 | F9: 500 | G9: HaileyA | H9: 44958 | I9: Full Payment
B10: Harvey Reyes | C10: Harvey_Reyes9354@voylg.directory | D10: Analytics | E10: 44925 | F10: 500 | G10: HarveyR | H10: 45017 | I10: Full Payment
B11: Carina Stubbs | C11: Carina_Stubbs8509@jh02o.org | D11: Accounting | E11: 44899 | F11: 500 | G11: CarinaS | H11: 44958 | I11: Full Payment
B12: Ramon Redden | C12: Ramon_Redden905@1kmd3.club | D12: Design and technology | E12: 44902 | F12: 500 | G12: RamonR | H12: 44958 | I12: Full Payment
B13: Matt Ashley | C13: Matt_Ashley6946@jh02o.info | D13: Analytics | E13: 44925 | F13: 100 | G13: MattA | H13: 45017 | I13: Half Payment
B14: Ronald Newton | C14: Ronald_Newton1403@1kmd3.com | D14: Design and technology | E14: 44917 | F14: 500 | G14: RonaldN | H14: 45017 | I14: Full Payment
B15: Jack Hobbs | C15: Jack_Hobbs4073@evyvh.auction | D15: Design and technology | E15: 44902 | F15: 500 | G15: JackH | H15: 44958 | I15: Full Payment
B16: Elena Shelton | C16: Elena_Shelton5238@karnv.org | D16: Analytics | E16: 44897 | F16: 500 | G16: ElenaS | H16: 44958 | I16: Full Payment
B17: Tom Alldridge | C17: Tom_Alldridge5905@gkvds.property | D17: Analytics | E17: 44905 | F17: 500 | G17: TomA | H17: 44958 | I17: Full Payment
B18: Henry Edmonds | C18: Henry_Edmonds4807@dbxli.store | D18: Analytics | E18: 44916 | F18: 500 | G18: HenryE | H18: 45017 | I18: Full Payment | K18: when we talk about Dashboard
B19: Jack Hudson | C19: Jack_Hudson8090@yafr7.audio | D19: Leadership | E19: 44921 | F19: 250 | G19: JackH | H19: 45017 | I19: Half Payment | K19: Consult Requirement with client
B20: Hadley Brown | C20: Hadley_Brown7577@xqj6f.business | D20: Leadership | E20: 44912 | F20: 500 | G20: HadleyB | H20: 45017 | I20: Full Payment | K20: decide design
B21: Carrie Simpson | C21: Carrie_Simpson7773@qu9ml.catering | D21: Analytics | E21: 44910 | F21: 250 | G21: CarrieS | H21: 45017 | I21: Half Payment | K21: data sources
B22: Harvey Bell | C22: Harvey_Bell7932@bu2lo.website | D22: Analytics | E22: 44898 | F22: 500 | G22: HarveyB | H22: 44958 | I22: Full Payment | K22: create first cut/Draft
B23: Barney Morris | C23: Barney_Morris5647@hepmv.autos | D23: Analytics | E23: 44919 | F23: 500 | G23: BarneyM | H23: 45017 | I23: Full Payment | K23: changes as per feedback and quality check
B24: Caydence Fisher | C24: Caydence_Fisher2480@bcfhs.store | D24: Leadership | E24: 44923 | F24: 500 | G24: CaydenceF | H24: 45017 | I24: Full Payment | K24: go live date
B25: Denny Bell | C25: Denny_Bell8404@cke3u.property | D25: Accounting | E25: 44911 | F25: 250 | G25: DennyB | H25: 45017 | I25: Half Payment | K25: Sop
B26: Nicole Norton | C26: Nicole_Norton7231@avn7d.zone | D26: Analytics | E26: 44918 | F26: 250 | G26: NicoleN | H26: 45017 | I26: Half Payment
B27: Daria Little | C27: Daria_Little6096@3wbkp.app | D27: Design and technology | E27: 44921 | F27: 250 | G27: DariaL | H27: 45017 | I27: Half Payment
B28: Lindsay Taylor | C28: Lindsay_Taylor7452@kyb7t.com | D28: Leadership | E28: 44898 | F28: 100 | G28: LindsayT | H28: 44958 | I28: Half Payment
B29: Mason Davies | C29: Mason_Davies1960@kyb7t.software | D29: Analytics | E29: 44913 | F29: 500 | G29: MasonD | H29: 45017 | I29: Full Payment
B30: Phoebe Morrison | C30: Phoebe_Morrison8611@xtwt3.store | D30: Design and technology | E30: 44915 | F30: 500 | G30: PhoebeM | H30: 45017 | I30: Full Payment
B31: Nate Thornton | C31: Nate_Thornton707@iaart.us | D31: Design and technology | E31: 44922 | F31: 100 | G31: NateT | H31: 45017 | I31: Half Payment
B32: Hayden Nanton | C32: Hayden_Nanton4520@yafr7.solutions | D32: Leadership | E32: 44905 | F32: 100 | G32: HaydenN | H32: 44958 | I32: Half Payment
B33: Evie Robe | C33: Evie_Robe9866@yahoo.mobi | D33: Analytics | E33: 44919 | F33: 100 | G33: EvieR | H33: 45017 | I33: Half Payment
B34: Mike Hunter | C34: Mike_Hunter6868@gkvds.digital | D34: Accounting | E34: 44922 | F34: 100 | G34: MikeH | H34: 45017 | I34: Half Payment
B35: Marilyn Jackson | C35: Marilyn_Jackson8632@gnjps.media | D35: Leadership | E35: 44903 | F35: 100 | G35: MarilynJ | H35: 44958 | I35: Half Payment
B36: Sloane Snell | C36: Sloane_Snell336@yahoo.page | D36: Analytics | E36: 44921 | F36: 250 | G36: SloaneS | H36: 45017 | I36: Half Payment
B37: Alessia Mcneill | C37: Alessia_Mcneill3403@bcfhs.services | D37: Design and technology | E37: 44908 | F37: 500 | G37: AlessiaM | H37: 44958 | I37: Full Payment
... B73: Elena Shelton | C73: Elena_Shelton5238@karnv.org | D73: Analytics | E73: 44897 | F73: 500 | G73: ElenaS | H73: 44958 | I73: Full Payment
